Workbook

Sheet Matches
A1: Match_id | B1: Season | C1: Match_no | D1: match_date | E1: Match_day | F1: Venue | G1: City | H1: Team_1 | I1: Team_2 | J1: Toss_winner | K1: Toss_decision | L1: Winner | M1: Win_type | N1: Win_margin | O1: Player_of_match | P1: match_type | Q1: Match_result | R1: Rain_interruption | S1: first_innings_score | T1: second_innings_score | U1: highest_team_total | V1: lowest_team_total | W1: umpires | X1: referee | Y1: Player of the series
A2: WPL2023_01 | B2: 2023 | C2: 1 | D2: 44989 | E2: Saturday | F2: Dr.DY Patil Sports | G2: Navi Mumbai | H2: GGTW | I2: MIW | J2: GGTW | K2: Field | L2: MIW | M2: Runs | N2: 143 | O2: Harmanpreet Kaur | P2: League | Q2: Normal | R2: No | S2: 207 | T2: 64 | U2: 207 | V2: 64 | W2: Nithin Pandit, Vrinda Rathi,Pashchim Pathak | X2: GS Lakshmi | Y2: Hayley Matthews
A3: WPL2023_02 | B3: 2023 | C3: 2 | D3: 44990 | E3: Sunday | F3: Brabourne Stadium | G3: Mumbai | H3: DCW | I3: RCBW | J3: RCBW | K3: Field | L3: DCW | M3: Runs | N3: 60 | O3: Tara Norris | P3: League | Q3: Normal | R3: No | S3: 223 | T3: 163 | U3: 223 | V3: 163 | W3: Chirra Ravikanthreddy, N Janani, Madanagopal Kuppuraj | X3: Rajni Basnet | Y3: Hayley Matthews
A4: WPL2023_03 | B4: 2023 | C4: 3 | D4: 44990 | E4: Sunday | F4: Dr DY Patil Sports | G4: Navi Mumbai | H4: UPW | I4: GGTW | J4: GGTW | K4: Batting | L4: UPW | M4: Wickets | N4: 3 | O4: Grace Harris | P4: League | Q4: Normal | R4: No | S4: 169 | T4: 175 | U4: 175 | V4: 169 | W4: Gayathri Venugopalan, Sanjay Kumar Singh, Pashchim Pathak | X4: Anupa Narvekar | Y4: Hayley Matthews
A5: WPL2023_04 | B5: 2023 | C5: 4 | D5: 44991 | E5: Monday | F5: Brabourne Stadium | G5: Mumbai | H5: RCBW | I5: MIW | J5: RCBW | K5: Batting | L5: MIW | M5: Wickets | N5: 9 | O5: Hayley Matthews | P5: League | Q5: Normal | R5: No | S5: 155 | T5: 159 | U5: 159 | V5: 155 | W5: Pashchim Pathak, Ranjeev Sharma, Saurabh Dhote | X5: Sanjay Kumar Singh | Y5: Hayley Matthews
A6: WPL2023_05 | B6: 2023 | C6: 5 | D6: 44992 | E6: Tuesday | F6: Dr.DY Patil Sports | G6: Navi Mumbai | H6: DCW | I6: UPW | J6: UPW | K6: Field | L6: DCW | M6: Runs | N6: 42 | O6: Jess Jonassen | P6: League | Q6: Normal | R6: No | S6: 211 | T6: 169 | U6: 211 | V6: 169 | W6: Chirra Ravikanthreddy, Vrinda Rathi, N Janani | X6: Rajni Basnet | Y6: Hayley Matthews
A7: WPL2023_06 | B7: 2023 | C7: 6 | D7: 44993 | E7: Wednesday | F7: Brabourne Stadium | G7: Mumbai | H7: GGTW | I7: RCBW | J7: GGTW | K7: Batting | L7: GGTW | M7: Runs | N7: 11 | O7: Sophia Dunkley | P7: League | Q7: Normal | R7: No | S7: 201 | T7: 190 | U7: 201 | V7: 190 | W7: Ranjeev Sharma, Sanjay Kumar Singh, Nitin Pandit | X7: GS Lakshmi | Y7: Hayley Matthews
A8: WPL2023_07 | B8: 2023 | C8: 7 | D8: 44994 | E8: Thursday | F8: Dr DY Patil Sports | G8: Navi Mumbai | H8: DCW | I8: MIW | J8: DCW | K8: Batting | L8: MIW | M8: Wickets | N8: 8 | O8: Saika Ishaque | P8: League | Q8: Normal | R8: No | S8: 105 | T8: 109 | U8: 109 | V8: 105 | W8: Madanagopal Kuppuraj, Vrinda Rathi, Pashchim Pathak | X8: Varsha Nagre | Y8: Hayley Matthews
A9: WPL2023_08 | B9: 2023 | C9: 8 | D9: 44995 | E9: Friday | F9: Brabourne Stadium | G9: Mumbai | H9: RCBW | I9: UPW | J9: RCBW | K9: Batting | L9: UPW | M9: Wickets | N9: 10 | O9: Alyssa Healy | P9: League | Q9: Normal | R9: No | S9: 138 | T9: 139 | U9: 139 | V9: 138 | W9: N Janani, Saurabh Dhote, Ranjeev Sharma | X9: Anupa Narvekar | Y9: Hayley Matthews
A10: WPL2023_09 | B10: 2023 | C10: 9 | D10: 44996 | E10: Saturday | F10: Dr DY Patil Sports | G10: Navi Mumbai | H10: GGTW | I10: DCW | J10: GGTW | K10: Batting | L10: DCW | M10: Wickets | N10: 10 | O10: Marizanne Kapp | P10: League | Q10: Normal | R10: No | S10: 105 | T10: 107 | U10: 107 | V10: 105 | W10: Gayathri Venugopalan, Sanjay Kumar Singh, Vrinda Rathi | X10: GS Lakshmi | Y10: Hayley Matthews
A11: WPL2023_10 | B11: 2023 | C11: 10 | D11: 44997 | E11: Sunday | F11: Brabourne Stadium | G11: Mumbai | H11: UPW | I11: MIW | J11: UPW | K11: Batting | L11: MIW | M11: Wickets | N11: 8 | O11: Harmanpreet Kaur | P11: League | Q11: Normal | R11: No | S11: 159 | T11: 164 | U11: 164 | V11: 159 | W11: N Janani, Pashchim Pathak, Chirra Ravikanthreddy | X11: Rajni Basnet | Y11: Hayley Matthews
A12: WPL2023_11 | B12: 2023 | C12: 11 | D12: 44998 | E12: Monday | F12: Dr DY Patil Sports | G12: Navi Mumbai | H12: DCW | I12: RCBW | J12: DCW | K12: Field | L12: DCW | M12: Wickets | N12: 6 | O12: Jess Jonassen | P12: League | Q12: Normal | R12: No | S12: 150 | T12: 154 | U12: 154 | V12: 150 | W12: Nitin Pandit, Saurabh Dhote, Madanagopal Kuppuraj | X12: Anupa Narvekar | Y12: Hayley Matthews
A13: WPL2023_12 | B13: 2023 | C13: 12 | D13: 44999 | E13: Tuesday | F13: Brabourne Stadium | G13: Mumbai | H13: MIW | I13: GGTW | J13: GGTW | K13: Field | L13: MIW | M13: Runs | N13: 55 | O13: Harmanpreet Kaur | P13: League | Q13: Normal | R13: No | S13: 162 | T13: 107 | U13: 162 | V13: 107 | W13: Chirra Ravikanthreddy, Gayathri Venugopalan, N Janani | X13: Varsha Nagre | Y13: Hayley Matthews
... A89: WPL2026_22 | B89: 2026 | C89: 88 | D89: 46058 | E89: Thursday | F89: BCA Stadium, Kotambi | G89: Vadodara | H89: DCW | I89: RCBW | J89: RCBW | K89: Field | L89: RCBW | M89: Wickets | N89: 6 | O89: Smriti Mandhana | P89: Final | Q89: Normal | R89: No | S89: 203 | T89: 204 | U89: 204 | V89: 203 | W89: Ankita Guha, Gayathri Venugopalan, Keyur Kelkar | X89: Varsha Nagre | Y89: Sophie Devine

Sheet Innings
A1: Match_id | B1: Season | C1: Innings_no | D1: batting_team | E1: bowling_team | F1: Total Runs | G1: Wickets_lost | H1: overs_played | I1: run_rate | J1: Powerplay_runs | K1: Powerplay_wickets | L1: Middleover_runs | M1: Middleover_wickets | N1: deathover_runs | O1: deathover_wickets | P1: Super_over | Q1: Total 4's | R1: Total 6's | S1: Dot_balls | T1: Extras | U1: biggest_over_runs | V1: required_rr_start | W1: chase_status
A2: WPL2023_01 | B2: 2023 | C2: 1 | D2: MIW | E2: GGTW | F2: 207 | G2: 5 | H2: 20 | I2: 10.35 | J2: 44 | K2: 1 | L2: 115 | M2: 2 | N2: 48 | O2: 2 | P2: 0 | Q2: 31 | R2: 6 | S2: 44 | T2: 1b, 4w | U2: 21 | V2: 0 | W2: NA
A3: WPL2023_01 | B3: 2023 | C3: 2 | D3: GGTW | E3: MIW | F3: 64 | G3: 10 | H3: 15.1 | I3: 4.22 | J3: 17 | K3: 4 | L3: 47 | M3: 6 | N3: 0 | O3: 0 | P3: 0 | Q3: 5 | R3: 2 | S3: 62 | T3: 2w | U3: 12 | V3: 10.35 | W3: Failed
A4: WPL2023_02 | B4: 2023 | C4: 1 | D4: DCW | E4: RCBW | F4: 223 | G4: 2 | H4: 20 | I4: 11.15 | J4: 57 | K4: 0 | L4: 120 | M4: 2 | N4: 46 | O4: 0 | P4: 0 | Q4: 30 | R4: 7 | S4: 28 | T4: 1lb, 5w | U4: 22 | V4: 0 | W4: NA
A5: WPL2023_02 | B5: 2023 | C5: 2 | D5: RCBW | E5: DCW | F5: 163 | G5: 8 | H5: 20 | I5: 8.15 | J5: 54 | K5: 1 | L5: 70 | M5: 6 | N5: 39 | O5: 1 | P5: 0 | Q5: 21 | R5: 3 | S5: 39 | T5: 1lb, 3w | U5: 16 | V5: 11.15 | W5: Failed
A6: WPL2023_03 | B6: 2023 | C6: 1 | D6: GGTW | E6: UPW | F6: 169 | G6: 6 | H6: 20 | I6: 8.45 | J6: 45 | K6: 2 | L6: 77 | M6: 3 | N6: 46 | O6: 1 | P6: 0 | Q6: 21 | R6: 2 | S6: 40 | T6: 1b, 1lb, 12w | U6: 18 | V6: 0 | W6: NA
A7: WPL2023_03 | B7: 2023 | C7: 2 | D7: UPW | E7: GGTW | F7: 175 | G7: 7 | H7: 19.5 | I7: 8.82 | J7: 35 | K7: 3 | L7: 72 | M7: 4 | N7: 68 | O7: 0 | P7: 0 | Q7: 15 | R7: 6 | S7: 33 | T7: 4b, 9w, 1nb | U7: 24 | V7: 8.45 | W7: Successful
A8: WPL2023_04 | B8: 2023 | C8: 1 | D8: RCBW | E8: MIW | F8: 155 | G8: 10 | H8: 18.4 | I8: 8.3 | J8: 47 | K8: 4 | L8: 85 | M8: 3 | N8: 22 | O8: 3 | P8: 0 | Q8: 21 | R8: 4 | S8: 41 | T8: 1lb, 6w | U8: 14 | V8: 0 | W8: NA
A9: WPL2023_04 | B9: 2023 | C9: 2 | D9: MIW | E9: RCBW | F9: 159 | G9: 1 | H9: 14.2 | I9: 11.09 | J9: 54 | K9: 1 | L9: 105 | M9: 0 | N9: 0 | O9: 0 | P9: 0 | Q9: 26 | R9: 2 | S9: 22 | T9: 4lb | U9: 20 | V9: 8.3 | W9: Successful
A10: WPL2023_05 | B10: 2023 | C10: 1 | D10: DCW | E10: UPW | F10: 211 | G10: 4 | H10: 20 | I10: 10.55 | J10: 62 | K10: 0 | L10: 91 | M10: 4 | N10: 58 | O10: 0 | P10: 0 | Q10: 21 | R10: 9 | S10: 35 | T10: 1b, 1lb, 9w | U10: 19 | V10: 0 | W10: NA
A11: WPL2023_05 | B11: 2023 | C11: 2 | D11: UPW | E11: DCW | F11: 169 | G11: 5 | H11: 20 | I11: 8.45 | J11: 33 | K11: 3 | L11: 80 | M11: 1 | N11: 56 | O11: 1 | P11: 0 | Q11: 20 | R11: 4 | S11: 45 | T11: 4lb, 7w | U11: 18 | V11: 10.55 | W11: Failed
A12: WPL2023_06 | B12: 2023 | C12: 1 | D12: GGTW | E12: RCBW | F12: 201 | G12: 7 | H12: 20 | I12: 10.05 | J12: 64 | K12: 1 | L12: 97 | M12: 3 | N12: 40 | O12: 3 | P12: 0 | Q12: 28 | R12: 6 | S12: 38 | T12: 1w, 1nb | U12: 23 | V12: 0 | W12: NA
A13: WPL2023_06 | B13: 2023 | C13: 2 | D13: RCBW | E13: GGTW | F13: 190 | G13: 6 | H13: 20 | I13: 9.5 | J13: 59 | K13: 1 | L13: 76 | M13: 2 | N13: 55 | O13: 3 | P13: 0 | Q13: 26 | R13: 4 | S13: 40 | T13: 5lb, 6w | U13: 23 | V13: 10.05 | W13: Failed
... A15: WPL2023_07 | B15: 2023 | C15: 2 | D15: MIW | E15: DCW | F15: 109 | G15: 2 | H15: 15 | I15: 7.27 | J15: 47 | K15: 0 | L15: 62 | M15: 2 | N15: 0 | O15: 0 | P15: 0 | Q15: 20 | R15: 0 | S15: 45 | T15: 1lb, 1w | U15: 13 | V15: 5.83 | W15: Successful
A16: WPL2023_08 | B16: 2023 | C16: 1 | D16: RCBW | E16: UPW | F16: 138 | G16: 10 | H16: 19.3 | I16: 7.08 | J16: 54 | K16: 1 | L16: 70 | M16: 4 | N16: 14 | O16: 5 | P16: 0 | Q16: 16 | R16: 2 | S16: 39 | T16: 0 | U16: 13 | V16: 0 | W16: NA
A17: WPL2023_08 | B17: 2023 | C17: 2 | D17: UPW | E17: RCBW | F17: 139 | G17: 0 | H17: 13 | I17: 10.69 | J17: 55 | K17: 0 | L17: 84 | M17: 0 | N17: 0 | O17: 0 | P17: 0 | Q17: 23 | R17: 1 | S17: 19 | T17: 1b, 5lb, 1w | U17: 18 | V17: 7.08 | W17: Successful
A18: WPL2023_09 | B18: 2023 | C18: 1 | D18: GGTW | E18: DCW | F18: 105 | G18: 9 | H18: 20 | I18: 5.25 | J18: 31 | K18: 5 | L18: 47 | M18: 2 | N18: 27 | O18: 2 | P18: 0 | Q18: 12 | R18: 0 | S18: 63 | T18: 2lb, 1w | U18: 9 | V18: 0 | W18: NA
A19: WPL2023_09 | B19: 2023 | C19: 2 | D19: DCW | E19: GGTW | F19: 107 | G19: 0 | H19: 7.1 | I19: 14.93 | J19: 87 | K19: 0 | L19: 20 | M19: 0 | N19: 0 | O19: 0 | P19: 0 | Q19: 13 | R19: 5 | S19: 9 | T19: 1b, 2lb, 7w | U19: 23 | V19: 5.25 | W19: Successful
A20: WPL2023_10 | B20: 2023 | C20: 1 | D20: UPW | E20: MIW | F20: 159 | G20: 6 | H20: 20 | I20: 7.95 | J20: 48 | K20: 1 | L20: 90 | M20: 1 | N20: 21 | O20: 4 | P20: 0 | Q20: 20 | R20: 2 | S20: 44 | T20: 5lb, 2w, 2nb | U20: 18 | V20: 0 | W20: NA
A21: WPL2023_10 | B21: 2023 | C21: 2 | D21: MIW | E21: UPW | F21: 164 | G21: 2 | H21: 17.3 | I21: 9.37 | J21: 51 | K21: 0 | L21: 91 | M21: 2 | N21: 22 | O21: 0 | P21: 0 | Q21: 25 | R21: 3 | S21: 48 | T21: 3b, 1lb, 5w, 3nb | U21: 19 | V21: 7.95 | W21: Successful
A22: WPL2023_11 | B22: 2023 | C22: 1 | D22: RCBW | E22: DCW | F22: 150 | G22: 4 | H22: 20 | I22: 7.5 | J22: 29 | K22: 1 | L22: 68 | M22: 2 | N22: 53 | O22: 1 | P22: 0 | Q22: 12 | R22: 8 | S22: 49 | T22: 2w | U22: 20 | V22: 0 | W22: NA
A23: WPL2023_11 | B23: 2023 | C23: 2 | D23: DCW | E23: RCBW | F23: 154 | G23: 4 | H23: 19.4 | I23: 7.83 | J23: 52 | K23: 2 | L23: 70 | M23: 2 | N23: 32 | O23: 0 | P23: 0 | Q23: 19 | R23: 2 | S23: 41 | T23: 4b, 4w | U23: 16 | V23: 7.5 | W23: Successful
A24: WPL2023_12 | B24: 2023 | C24: 1 | D24: MIW | E24: GGTW | F24: 162 | G24: 8 | H24: 20 | I24: 8.1 | J24: 40 | K24: 1 | L24: 84 | M24: 2 | N24: 38 | O24: 5 | P24: 0 | Q24: 19 | R24: 4 | S24: 44 | T24: 5b, 1lb, 1w | U24: 14 | V24: 0 | W24: NA
A25: WPL2023_12 | B25: 2023 | C25: 2 | D25: GGTW | E25: MIW | F25: 107 | G25: 9 | H25: 20 | I25: 5.35 | J25: 34 | K25: 3 | L25: 59 | M25: 4 | N25: 14 | O25: 2 | P25: 0 | Q25: 14 | R25: 0 | S25: 54 | T25: 2w | U25: 11 | V25: 8.1 | W25: Failed
A26: WPL2023_13 | B26: 2023 | C26: 1 | D26: UPW | E26: RCBW | F26: 135 | G26: 10 | H26: 19.3 | I26: 6.92 | J26: 29 | K26: 3 | L26: 74 | M26: 4 | N26: 32 | O26: 3 | P26: 0 | Q26: 15 | R26: 3 | S26: 52 | T26: 1b, 6lb, 5w | U26: 16 | V26: 0 | W26: NA
A27: WPL2023_13 | B27: 2023 | C27: 2 | D27: RCBW | E27: UPW | F27: 136 | G27: 5 | H27: 18 | I27: 7.56 | J27: 43 | K27: 2 | L27: 76 | M27: 2 | N27: 17 | O27: 1 | P27: 0 | Q27: 20 | R27: 3 | S27: 53 | T27: 4b, 2w | U27: 14 | V27: 6.92 | W27: Successful
A28: WPL2023_14 | B28: 2023 | C28: 1 | D28: GGTW | E28: DCW | F28: 147 | G28: 4 | H28: 20 | I28: 7.35 | J28: 32 | K28: 1 | L28: 77 | M28: 1 | N28: 38 | O28: 2 | P28: 0 | Q28: 19 | R28: 1 | S28: 46 | T28: 2lb, 1w | U28: 15 | V28: 0 | W28: NA
... A74: WPL2024_15 | B74: 2024 | C74: 1 | D74: UPW | E74: DCW | F74: 138 | G74: 8 | H74: 20 | I74: 6.9 | J74: 44 | K74: 1 | L74: 65 | M74: 5 | N74: 29 | O74: 2 | P74: 0 | Q74: 14 | R74: 2 | S74: 40 | T74: 2lb, 6w, 1nb | U74: 14 | V74: 0 | W74: NA
A75: WPL2024_15 | B75: 2024 | C75: 2 | D75: DCW | E75: UPW | F75: 137 | G75: 10 | H75: 19.5 | I75: 6.91 | J75: 35 | K75: 1 | L75: 76 | M75: 2 | N75: 26 | O75: 7 | P75: 0 | Q75: 18 | R75: 4 | S75: 48 | T75: 0 | U75: 15 | V75: 6.9 | W75: Failed
A76: WPL2024_16 | B76: 2024 | C76: 1 | D76: GGTW | E76: MIW | F76: 190 | G76: 7 | H76: 20 | I76: 9.5 | J76: 52 | K76: 1 | L76: 108 | M76: 3 | N76: 30 | O76: 3 | P76: 0 | Q76: 22 | R76: 6 | S76: 34 | T76: 3lb, 1w | U76: 16 | V76: 0 | W76: NA
A77: WPL2024_16 | B77: 2024 | C77: 2 | D77: MIW | E77: GGTW | F77: 191 | G77: 3 | H77: 19.5 | I77: 9.63 | J77: 50 | K77: 0 | L77: 76 | M77: 3 | N77: 65 | O77: 0 | P77: 0 | Q77: 22 | R77: 7 | S77: 43 | T77: 4b, 4lb, 7w | U77: 24 | V77: 9.5 | W77: Successful
A78: WPL2024_17 | B78: 2024 | C78: 1 | D78: DCW | E78: RCBW | F78: 181 | G78: 5 | H78: 20 | I78: 9.05 | J78: 53 | K78: 0 | L78: 90 | M78: 2 | N78: 38 | O78: 3 | P78: 0 | Q78: 24 | R78: 3 | S78: 34 | T78: 1lb, 7w, 1nb | U78: 20 | V78: 0 | W78: NA
A79: WPL2024_17 | B79: 2024 | C79: 2 | D79: RCBW | E79: DCW | F79: 180 | G79: 7 | H79: 20 | I79: 9 | J79: 42 | K79: 1 | L79: 95 | M79: 2 | N79: 43 | O79: 4 | P79: 0 | Q79: 20 | R79: 6 | S79: 35 | T79: 4w | U79: 17 | V79: 9.05 | W79: Failed
A80: WPL2024_18 | B80: 2024 | C80: 1 | D80: GGTW | E80: UPW | F80: 152 | G80: 8 | H80: 20 | I80: 7.6 | J80: 53 | K80: 0 | L80: 58 | M80: 5 | N80: 41 | O80: 3 | P80: 0 | Q80: 21 | R80: 3 | S80: 44 | T80: 3w | U80: 21 | V80: 0 | W80: NA
A81: WPL2024_18 | B81: 2024 | C81: 2 | D81: UPW | E81: GGTW | F81: 144 | G81: 5 | H81: 20 | I81: 7.2 | J81: 30 | K81: 4 | L81: 68 | M81: 1 | N81: 46 | O81: 0 | P81: 0 | Q81: 15 | R81: 5 | S81: 51 | T81: 5b, 2w | U81: 17 | V81: 7.6 | W81: Failed
A82: WPL2024_19 | B82: 2024 | C82: 1 | D82: MIW | E82: RCBW | F82: 113 | G82: 10 | H82: 19 | I82: 5.95 | J82: 43 | K82: 1 | L82: 56 | M82: 7 | N82: 14 | O82: 2 | P82: 0 | Q82: 13 | R82: 3 | S82: 55 | T82: 3lb | U82: 15 | V82: 0 | W82: NA
A83: WPL2024_19 | B83: 2024 | C83: 2 | D83: RCBW | E83: MIW | F83: 115 | G83: 3 | H83: 15 | I83: 7.67 | J83: 39 | K83: 2 | L83: 76 | M83: 1 | N83: 0 | O83: 0 | P83: 0 | Q83: 14 | R83: 3 | S83: 44 | T83: 4b, 11w | U83: 15 | V83: 5.95 | W83: Successful
A84: WPL2024_20 | B84: 2024 | C84: 1 | D84: GGTW | E84: DCW | F84: 126 | G84: 9 | H84: 20 | I84: 6.3 | J84: 23 | K84: 3 | L84: 67 | M84: 2 | N84: 36 | O84: 4 | P84: 0 | Q84: 17 | R84: 1 | S84: 57 | T84: 1b, 4lb, 2w | U84: 11 | V84: 0 | W84: NA
A85: WPL2024_20 | B85: 2024 | C85: 2 | D85: DCW | E85: GGTW | F85: 129 | G85: 3 | H85: 13.1 | I85: 9.8 | J85: 45 | K85: 2 | L85: 85 | M85: 1 | N85: 0 | O85: 0 | P85: 0 | Q85: 15 | R85: 6 | S85: 30 | T85: 2w | U85: 20 | V85: 6.3 | W85: Successful
A86: WPL2024_21 | B86: 2024 | C86: 1 | D86: RCBW | E86: MIW | F86: 135 | G86: 6 | H86: 20 | I86: 6.75 | J86: 34 | K86: 3 | L86: 56 | M86: 2 | N86: 45 | O86: 1 | P86: 0 | Q86: 15 | R86: 3 | S86: 48 | T86: 3lb | U86: 14 | V86: 0 | W86: NA
...

Sheet Rank_players
A3: Row Labels | B3: Average of Final_Score | C3: Sum of runs_scored | D3: Sum of wickets_taken
A4: Danielle Gibson | B4: 50.5 | C4: 34 | D4: 2
A5: Nat Sciver-Brunt | B5: 49.273333 | C5: 1348 | D5: 40
A6: Nadine de Klerk | B6: 46.04 | C6: 134 | D6: 18
A7: Hayley Matthews | B7: 44.662206 | C7: 867 | D7: 46
A8: Nicola Carey | B8: 40.233333 | C8: 149 | D8: 7
A9: Ellyse Perry | B9: 40.2278 | C9: 972 | D9: 14
A10: Amelia Kerr | B10: 39.247083 | C10: 511 | D10: 54
A11: Sophie Devine | B11: 38.752222 | C11: 645 | D11: 26
A12: Chinelle Henry | B12: 38.093333 | C12: 271 | D12: 20
A13: Nallapureddy Charani | B13: 37.25 | C13: 3 | D13: 4
A14: Jess Jonassen | B14: 36.6025 | C14: 295 | D14: 33
A15: Lauren Bell | B15: 36.266667 | C15: 1 | D15: 12
... A70: Rajeshwari Gayakwad | B70: 20.032 | C70: 8 | D70: 24
A71: (blank) | B71: 20
A72: Deeya Yadav | B72: 20 | C72: 0 | D72: 0
A73: Laura Harris | B73: 20 | C73: 0 | D73: 0
A74: Titas Sadhu | B74: 19.985714 | C74: 0 | D74: 3
A75: Asha Shobana | B75: 19.467391 | C75: 55 | D75: 20
A76: G Kamalini | B76: 19.372727 | C76: 80 | D76: 0
A77: Devika Vaidya | B77: 19.290714 | C77: 77 | D77: 1
A78: Chamari Athapaththu | B78: 19.2875 | C78: 28 | D78: 3
A79: Priya Mishra | B79: 19.211111 | C79: 4 | D79: 6
A80: Minnu Mani | B80: 18.957692 | C80: 28 | D80: 15
A81: S Sajana | B81: 18.9 | C81: 241 | D81: 3
A82: Parunika Sisodia | B82: 18.68 | C82: 0 | D82: 1
A83: Tanuja Kanwar | B83: 17.838182 | C83: 168 | D83: 23
... A142: Grand Total | B142: 25.107951 | C142: 26071 | D142: 990

Sheet Match_Model_Data
A3: Row Labels | B3: Sum of runs_scored | C3: Average of Run_rate | D3: Sum of wickets_taken | E3: Average of Dot_balls | F3: Winner
A4: WPL2023_01 | B4: 264 | C4: 7.285 | D4: 14 | E4: 53 | F4: =_xlfn.XLOOKUP(A2, Matches!A:A, Matches!L:L) -> 0
A5: GGTW | B5: 62 | C5: 4.22 | D5: 5 | E5: 62 | F5: =_xlfn.XLOOKUP(A3, Matches!A:A, Matches!L:L) -> #N/A
A6: MIW | B6: 202 | C6: 10.35 | D6: 9 | E6: 44 | F6: =_xlfn.XLOOKUP(A4, Matches!A:A, Matches!L:L) -> MIW
A7: WPL2023_02 | B7: 376 | C7: 9.65 | D7: 10 | E7: 33.5 | F7: =_xlfn.XLOOKUP(A5, Matches!A:A, Matches!L:L) -> #N/A
A8: DCW | B8: 217 | C8: 11.15 | D8: 8 | E8: 28 | F8: =_xlfn.XLOOKUP(A6, Matches!A:A, Matches!L:L) -> #N/A
A9: RCBW | B9: 159 | C9: 8.15 | D9: 2 | E9: 39 | F9: =_xlfn.XLOOKUP(A7, Matches!A:A, Matches!L:L) -> DCW
A10: WPL2023_03 | B10: 316 | C10: 8.635 | D10: 13 | E10: 36.5 | F10: =_xlfn.XLOOKUP(A8, Matches!A:A, Matches!L:L) -> #N/A
A11: GGTW | B11: 155 | C11: 8.45 | D11: 7 | E11: 40 | F11: =_xlfn.XLOOKUP(A9, Matches!A:A, Matches!L:L) -> #N/A
A12: UPW | B12: 161 | C12: 8.82 | D12: 6 | E12: 33 | F12: =_xlfn.XLOOKUP(A10, Matches!A:A, Matches!L:L) -> UPW
A13: WPL2023_04 | B13: 303 | C13: 9.695 | D13: 10 | E13: 31.5 | F13: =_xlfn.XLOOKUP(A11, Matches!A:A, Matches!L:L) -> #N/A
A14: MIW | B14: 155 | C14: 11.09 | D14: 9 | E14: 22 | F14: =_xlfn.XLOOKUP(A12, Matches!A:A, Matches!L:L) -> #N/A
A15: RCBW | B15: 148 | C15: 8.3 | D15: 1 | E15: 41 | F15: =_xlfn.XLOOKUP(A13, Matches!A:A, Matches!L:L) -> MIW
... A22: WPL2023_07 | B22: 205 | C22: 6.55 | D22: 12 | E22: 44 | F22: =_xlfn.XLOOKUP(A20, Matches!A:A, Matches!L:L) -> #N/A
A23: DCW | B23: 98 | C23: 5.83 | D23: 2 | E23: 43
A24: MIW | B24: 107 | C24: 7.27 | D24: 10 | E24: 45
A25: WPL2023_08 | B25: 270 | C25: 8.885 | D25: 5 | E25: 29
A26: RCBW | B26: 138 | C26: 7.08 | D26: 0 | E26: 39
A27: UPW | B27: 132 | C27: 10.69 | D27: 5 | E27: 19
A28: WPL2023_09 | B28: 199 | C28: 10.09 | D28: 9 | E28: 36
A29: DCW | B29: 97 | C29: 14.93 | D29: 9 | E29: 9
A30: GGTW | B30: 102 | C30: 5.25 | D30: 0 | E30: 63
A31: WPL2023_10 | B31: 302 | C31: 8.66 | D31: 8 | E31: 46
A32: MIW | B32: 152 | C32: 9.37 | D32: 6 | E32: 48
A33: UPW | B33: 150 | C33: 7.95 | D33: 2 | E33: 44
A34: WPL2023_11 | B34: 294 | C34: 7.665 | D34: 8 | E34: 45
... A267: RCBW | B267: 200 | C267: 10.37 | D267: 3 | E267: 24
A268: (blank) | C268: 0 | E268: 0
A269: (blank) | C269: 0 | E269: 0
A270: Grand Total | B270: 26071 | C270: 8.266935 | D270: 990 | E270: 41.23839

Sheet Match_Model_Data_Final
A1: Match_id | B1: Team | C1: Sums of runs_scored | D1: Average of Run_rate | E1: Sum of wickets_taken | F1: Average of Dot_balls | G1: Winner | H1: Target
A2: WPL2023_01 | B2: GGTW | C2: 62 | D2: 4.22 | E2: 5 | F2: 62 | G2: =_xlfn.XLOOKUP(A2,Matches!A:A,Matches!L:L,"") -> MIW | H2: =IF(B2=G2,1,0) -> 0
A3: WPL2023_01 | B3: MIW | C3: 202 | D3: 10.35 | E3: 9 | F3: 44 | G3: =_xlfn.XLOOKUP(A3,Matches!A:A,Matches!L:L,"") -> MIW | H3: =IF(B3=G3,1,0) -> 1
A4: WPL2023_02 | B4: DCW | C4: 217 | D4: 11.15 | E4: 8 | F4: 28 | G4: =_xlfn.XLOOKUP(A4,Matches!A:A,Matches!L:L,"") -> DCW | H4: =IF(B4=G4,1,0) -> 1
A5: WPL2023_02 | B5: RCBW | C5: 159 | D5: 8.15 | E5: 2 | F5: 39 | G5: =_xlfn.XLOOKUP(A5,Matches!A:A,Matches!L:L,"") -> DCW | H5: =IF(B5=G5,1,0) -> 0
A6: WPL2023_03 | B6: GGTW | C6: 155 | D6: 8.45 | E6: 7 | F6: 40 | G6: =_xlfn.XLOOKUP(A6,Matches!A:A,Matches!L:L,"") -> UPW | H6: =IF(B6=G6,1,0) -> 0
A7: WPL2023_03 | B7: UPW | C7: 161 | D7: 8.82 | E7: 6 | F7: 33 | G7: =_xlfn.XLOOKUP(A7,Matches!A:A,Matches!L:L,"") -> UPW | H7: =IF(B7=G7,1,0) -> 1
A8: WPL2023_04 | B8: MIW | C8: 155 | D8: 11.09 | E8: 9 | F8: 22 | G8: =_xlfn.XLOOKUP(A8,Matches!A:A,Matches!L:L,"") -> MIW | H8: =IF(B8=G8,1,0) -> 1
A9: WPL2023_04 | B9: RCBW | C9: 148 | D9: 8.3 | E9: 1 | F9: 41 | G9: =_xlfn.XLOOKUP(A9,Matches!A:A,Matches!L:L,"") -> MIW | H9: =IF(B9=G9,1,0) -> 0
A10: WPL2023_05 | B10: DCW | C10: 200 | D10: 10.55 | E10: 5 | F10: 35 | G10: =_xlfn.XLOOKUP(A10,Matches!A:A,Matches!L:L,"") -> DCW | H10: =IF(B10=G10,1,0) -> 1
A11: WPL2023_05 | B11: UPW | C11: 158 | D11: 8.45 | E11: 4 | F11: 45 | G11: =_xlfn.XLOOKUP(A11,Matches!A:A,Matches!L:L,"") -> DCW | H11: =IF(B11=G11,1,0) -> 0
A12: WPL2023_06 | B12: GGTW | C12: 199 | D12: 10.05 | E12: 6 | F12: 38 | G12: =_xlfn.XLOOKUP(A12,Matches!A:A,Matches!L:L,"") -> GGTW | H12: =IF(B12=G12,1,0) -> 1
A13: WPL2023_06 | B13: RCBW | C13: 179 | D13: 9.5 | E13: 6 | F13: 40 | G13: =_xlfn.XLOOKUP(A13,Matches!A:A,Matches!L:L,"") -> GGTW | H13: =IF(B13=G13,1,0) -> 0
... A177: WPL2026_22 | B177: RCBW | C177: 200 | D177: 10.37 | E177: 3 | F177: 24 | G177: =_xlfn.XLOOKUP(A177,Matches!A:A,Matches!L:L,"") -> RCBW | H177: =IF(B177=G177,1,0) -> 1

Sheet Players ALL
A1: Match_id | B1: Season | C1: Player_id | D1: player_name | E1: team | F1: role | G1: battin_position | H1: runs_scored | I1: balls_faced | J1: strike_rate | K1: dismissal_type | L1: batting_impact_score | M1: overs_bowled | N1: maidens | O1: runs_conceded | P1: wickets_taken | Q1: economy | R1: bowling_impact_score | S1: catches | T1: runouts | U1: total_player_impact | V1: player_match_rating | W1: Winner | X1: Toss_winner | Y1: Venue | Z1: Team_Total_Runs | AA1: Run_rate | AB1: Powerplay_runs | AC1: Deathover_runs | AD1: Dot_balls | AE1: Chase_status | AF1: Is_Winner | AG1: Final_Score
A2: WPL2023_01 | B2: 1 | C2: P001 | D2: Beth Mooney | E2: GGTW | F2: WK-Batter | G2: Opener | H2: 0 | I2: 3 | J2: 0 | K2: retired out | L2: 0 | M2: 0 | N2: 0 | O2: 0 | P2: 0 | Q2: 0 | R2: 0 | S2: 0 | T2: 0 | U2: 0 | V2: =MIN(10, MAX(0, ROUND(U2/10,0))) -> 0 | W2: =_xlfn.XLOOKUP(A2, Matches!A:A, Matches!L:L, "NA", 0) -> MIW | X2: =_xlfn.XLOOKUP(A2, Matches!A:A, Matches!J:J, "NA", 0) -> GGTW | Y2: =_xlfn.XLOOKUP(A2, Matches!A:A, Matches!F:F, "NA", 0) -> Dr.DY Patil Sports | Z2: {=INDEX(Innings!F:F,MATCH(1,(TRIM(Innings!A:A)=TRIM(A2))*(TRIM(Innings!D:D)=TRIM(E2)),0))} -> 64 | AA2: {=INDEX(Innings!I:I,MATCH(1,(TRIM(Innings!A:A)=TRIM(A2))*(TRIM(Innings!D:D)=TRIM(E2)),0))} -> 4.22 | AB2: {=INDEX(Innings!J:J,MATCH(1,(TRIM(Innings!A:A)=TRIM(A2))*(TRIM(Innings!D:D)=TRIM(E2)),0))} -> 17 | AC2: {=INDEX(Innings!N:N,MATCH(1,(TRIM(Innings!A:A)=TRIM(A2))*(TRIM(Innings!D:D)=TRIM(E2)),0))} -> 0 | AD2: {=INDEX(Innings!S:S,MATCH(1,(TRIM(Innings!A:A)=TRIM(A2))*(TRIM(Innings!D:D)=TRIM(E2)),0))} -> 62 | AE2: {=INDEX(Innings!W:W,MATCH(1,(TRIM(Innings!A:A)=TRIM(A2))*(TRIM(Innings!D:D)=TRIM(E2)),0))} -> Failed | AF2: =IF(UPPER(TRIM(E2))=UPPER(TRIM(W2)),1,0) -> 0 | AG2: =(0.5*MAX(0,U2) + 0.3*MAX(0,V2) + 0.2*AF2*100) -> 0
A3: WPL2023_01 | B3: 1 | C3: P002 | D3: Sabbhineni Meghana | E3: GGTW | F3: Batter | G3: Opener | H3: 2 | I3: 4 | J3: 50 | K3: bowled | L3: 1 | M3: 0 | N3: 0 | O3: 0 | P3: 0 | Q3: 0 | R3: 0 | S3: 0 | T3: 0 | U3: 1 | V3: =MIN(10, MAX(0, ROUND(U3/10,0))) -> 0 | W3: =_xlfn.XLOOKUP(A3, Matches!A:A, Matches!L:L, "NA", 0) -> MIW | X3: =_xlfn.XLOOKUP(A3, Matches!A:A, Matches!J:J, "NA", 0) -> GGTW | Y3: =_xlfn.XLOOKUP(A3, Matches!A:A, Matches!F:F, "NA", 0) -> Dr.DY Patil Sports | Z3: {=INDEX(Innings!F:F,MATCH(1,(TRIM(Innings!A:A)=TRIM(A3))*(TRIM(Innings!D:D)=TRIM(E3)),0))} -> 64 | AA3: {=INDEX(Innings!I:I,MATCH(1,(TRIM(Innings!A:A)=TRIM(A3))*(TRIM(Innings!D:D)=TRIM(E3)),0))} -> 4.22 | AB3: {=INDEX(Innings!J:J,MATCH(1,(TRIM(Innings!A:A)=TRIM(A3))*(TRIM(Innings!D:D)=TRIM(E3)),0))} -> 17 | AC3: {=INDEX(Innings!N:N,MATCH(1,(TRIM(Innings!A:A)=TRIM(A3))*(TRIM(Innings!D:D)=TRIM(E3)),0))} -> 0 | AD3: {=INDEX(Innings!S:S,MATCH(1,(TRIM(Innings!A:A)=TRIM(A3))*(TRIM(Innings!D:D)=TRIM(E3)),0))} -> 62 | AE3: {=INDEX(Innings!W:W,MATCH(1,(TRIM(Innings!A:A)=TRIM(A3))*(TRIM(Innings!D:D)=TRIM(E3)),0))} -> Failed | AF3: =IF(UPPER(TRIM(E3))=UPPER(TRIM(W3)),1,0) -> 0 | AG3: =(0.5*MAX(0,U3) + 0.3*MAX(0,V3) + 0.2*AF3*100) -> 0.5
A4: WPL2023_01 | B4: 1 | C4: P003 | D4: Harleen Deol | E4: GGTW | F4: Batting Allrounder | G4: Top Order | H4: 0 | I4: 2 | J4: 0 | K4: caught | L4: 0 | M4: 0 | N4: 0 | O4: 0 | P4: 0 | Q4: 0 | R4: 0 | S4: 0 | T4: 0 | U4: 0 | V4: =MIN(10, MAX(0, ROUND(U4/10,0))) -> 0 | W4: =_xlfn.XLOOKUP(A4, Matches!A:A, Matches!L:L, "NA", 0) -> MIW | X4: =_xlfn.XLOOKUP(A4, Matches!A:A, Matches!J:J, "NA", 0) -> GGTW | Y4: =_xlfn.XLOOKUP(A4, Matches!A:A, Matches!F:F, "NA", 0) -> Dr.DY Patil Sports | Z4: {=INDEX(Innings!F:F,MATCH(1,(TRIM(Innings!A:A)=TRIM(A4))*(TRIM(Innings!D:D)=TRIM(E4)),0))} -> 64 | AA4: {=INDEX(Innings!I:I,MATCH(1,(TRIM(Innings!A:A)=TRIM(A4))*(TRIM(Innings!D:D)=TRIM(E4)),0))} -> 4.22 | AB4: {=INDEX(Innings!J:J,MATCH(1,(TRIM(Innings!A:A)=TRIM(A4))*(TRIM(Innings!D:D)=TRIM(E4)),0))} -> 17 | AC4: {=INDEX(Innings!N:N,MATCH(1,(TRIM(Innings!A:A)=TRIM(A4))*(TRIM(Innings!D:D)=TRIM(E4)),0))} -> 0 | AD4: {=INDEX(Innings!S:S,MATCH(1,(TRIM(Innings!A:A)=TRIM(A4))*(TRIM(Innings!D:D)=TRIM(E4)),0))} -> 62 | AE4: {=INDEX(Innings!W:W,MATCH(1,(TRIM(Innings!A:A)=TRIM(A4))*(TRIM(Innings!D:D)=TRIM(E4)),0))} -> Failed | AF4: =IF(UPPER(TRIM(E4))=UPPER(TRIM(W4)),1,0) -> 0 | AG4: =(0.5*MAX(0,U4) + 0.3*MAX(0,V4) + 0.2*AF4*100) -> 0
A5: WPL2023_01 | B5: 1 | C5: P004 | D5: Ashleigh Gardner | E5: GGTW | F5: Batting Allrounder | G5: Middle Order | H5: 0 | I5: 1 | J5: 0 | K5: caught | L5: 0 | M5: 4 | N5: 0 | O5: 38 | P5: 1 | Q5: 9.5 | R5: 6 | S5: 0 | T5: 0 | U5: 6 | V5: =MIN(10, MAX(0, ROUND(U5/10,0))) -> 1 | W5: =_xlfn.XLOOKUP(A5, Matches!A:A, Matches!L:L, "NA", 0) -> MIW | X5: =_xlfn.XLOOKUP(A5, Matches!A:A, Matches!J:J, "NA", 0) -> GGTW | Y5: =_xlfn.XLOOKUP(A5, Matches!A:A, Matches!F:F, "NA", 0) -> Dr.DY Patil Sports | Z5: {=INDEX(Innings!F:F,MATCH(1,(TRIM(Innings!A:A)=TRIM(A5))*(TRIM(Innings!D:D)=TRIM(E5)),0))} -> 64 | AA5: {=INDEX(Innings!I:I,MATCH(1,(TRIM(Innings!A:A)=TRIM(A5))*(TRIM(Innings!D:D)=TRIM(E5)),0))} -> 4.22 | AB5: {=INDEX(Innings!J:J,MATCH(1,(TRIM(Innings!A:A)=TRIM(A5))*(TRIM(Innings!D:D)=TRIM(E5)),0))} -> 17 | AC5: {=INDEX(Innings!N:N,MATCH(1,(TRIM(Innings!A:A)=TRIM(A5))*(TRIM(Innings!D:D)=TRIM(E5)),0))} -> 0 | AD5: {=INDEX(Innings!S:S,MATCH(1,(TRIM(Innings!A:A)=TRIM(A5))*(TRIM(Innings!D:D)=TRIM(E5)),0))} -> 62 | AE5: {=INDEX(Innings!W:W,MATCH(1,(TRIM(Innings!A:A)=TRIM(A5))*(TRIM(Innings!D:D)=TRIM(E5)),0))} -> Failed | AF5: =IF(UPPER(TRIM(E5))=UPPER(TRIM(W5)),1,0) -> 0 | AG5: =(0.5*MAX(0,U5) + 0.3*MAX(0,V5) + 0.2*AF5*100) -> 3.3
A6: WPL2023_01 | B6: 1 | C6: P005 | D6: Annabel Sutherland | E6: GGTW | F6: Bowling Allrounder | G6: Middle Order | H6: 6 | I6: 14 | J6: 42.86 | K6: bowled | L6: 2.57 | M6: 3 | N6: 0 | O6: 32 | P6: 0 | Q6: 10.7 | R6: -21.4 | S6: 0 | T6: 0 | U6: -18.83 | V6: =MIN(10, MAX(0, ROUND(U6/10,0))) -> 0 | W6: =_xlfn.XLOOKUP(A6, Matches!A:A, Matches!L:L, "NA", 0) -> MIW | X6: =_xlfn.XLOOKUP(A6, Matches!A:A, Matches!J:J, "NA", 0) -> GGTW | Y6: =_xlfn.XLOOKUP(A6, Matches!A:A, Matches!F:F, "NA", 0) -> Dr.DY Patil Sports | Z6: {=INDEX(Innings!F:F,MATCH(1,(TRIM(Innings!A:A)=TRIM(A6))*(TRIM(Innings!D:D)=TRIM(E6)),0))} -> 64 | AA6: {=INDEX(Innings!I:I,MATCH(1,(TRIM(Innings!A:A)=TRIM(A6))*(TRIM(Innings!D:D)=TRIM(E6)),0))} -> 4.22 | AB6: {=INDEX(Innings!J:J,MATCH(1,(TRIM(Innings!A:A)=TRIM(A6))*(TRIM(Innings!D:D)=TRIM(E6)),0))} -> 17 | AC6: {=INDEX(Innings!N:N,MATCH(1,(TRIM(Innings!A:A)=TRIM(A6))*(TRIM(Innings!D:D)=TRIM(E6)),0))} -> 0 | AD6: {=INDEX(Innings!S:S,MATCH(1,(TRIM(Innings!A:A)=TRIM(A6))*(TRIM(Innings!D:D)=TRIM(E6)),0))} -> 62 | AE6: {=INDEX(Innings!W:W,MATCH(1,(TRIM(Innings!A:A)=TRIM(A6))*(TRIM(Innings!D:D)=TRIM(E6)),0))} -> Failed | AF6: =IF(UPPER(TRIM(E6))=UPPER(TRIM(W6)),1,0) -> 0 | AG6: =(0.5*MAX(0,U6) + 0.3*MAX(0,V6) + 0.2*AF6*100) -> 0
A7: WPL2023_01 | B7: 1 | C7: P006 | D7: Dayalan Hemalatha | E7: GGTW | F7: Batter | G7: Middle Order | H7: 29 | I7: 23 | J7: 126.09 | K7: not out | L7: 36.57 | M7: 0 | N7: 0 | O7: 0 | P7: 0 | Q7: 0 | R7: 0 | S7: 0 | T7: 0 | U7: 36.57 | V7: =MIN(10, MAX(0, ROUND(U7/10,0))) -> 4 | W7: =_xlfn.XLOOKUP(A7, Matches!A:A, Matches!L:L, "NA", 0) -> MIW | X7: =_xlfn.XLOOKUP(A7, Matches!A:A, Matches!J:J, "NA", 0) -> GGTW | Y7: =_xlfn.XLOOKUP(A7, Matches!A:A, Matches!F:F, "NA", 0) -> Dr.DY Patil Sports | Z7: {=INDEX(Innings!F:F,MATCH(1,(TRIM(Innings!A:A)=TRIM(A7))*(TRIM(Innings!D:D)=TRIM(E7)),0))} -> 64 | AA7: {=INDEX(Innings!I:I,MATCH(1,(TRIM(Innings!A:A)=TRIM(A7))*(TRIM(Innings!D:D)=TRIM(E7)),0))} -> 4.22 | AB7: {=INDEX(Innings!J:J,MATCH(1,(TRIM(Innings!A:A)=TRIM(A7))*(TRIM(Innings!D:D)=TRIM(E7)),0))} -> 17 | AC7: {=INDEX(Innings!N:N,MATCH(1,(TRIM(Innings!A:A)=TRIM(A7))*(TRIM(Innings!D:D)=TRIM(E7)),0))} -> 0 | AD7: {=INDEX(Innings!S:S,MATCH(1,(TRIM(Innings!A:A)=TRIM(A7))*(TRIM(Innings!D:D)=TRIM(E7)),0))} -> 62 | AE7: {=INDEX(Innings!W:W,MATCH(1,(TRIM(Innings!A:A)=TRIM(A7))*(TRIM(Innings!D:D)=TRIM(E7)),0))} -> Failed | AF7: =IF(UPPER(TRIM(E7))=UPPER(TRIM(W7)),1,0) -> 0 | AG7: =(0.5*MAX(0,U7) + 0.3*MAX(0,V7) + 0.2*AF7*100) -> 19.485
A8: WPL2023_01 | B8: 1 | C8: P007 | D8: Georgia Wareham | E8: GGTW | F8: Bowler | G8: Lower Order | H8: 8 | I8: 11 | J8: 72.73 | K8: bowled | L8: 5.82 | M8: 3 | N8: 0 | O8: 30 | P8: 1 | Q8: 10 | R8: 5 | S8: 0 | T8: 0 | U8: 10.82 | V8: =MIN(10, MAX(0, ROUND(U8/10,0))) -> 1 | W8: =_xlfn.XLOOKUP(A8, Matches!A:A, Matches!L:L, "NA", 0) -> MIW | X8: =_xlfn.XLOOKUP(A8, Matches!A:A, Matches!J:J, "NA", 0) -> GGTW | Y8: =_xlfn.XLOOKUP(A8, Matches!A:A, Matches!F:F, "NA", 0) -> Dr.DY Patil Sports | Z8: {=INDEX(Innings!F:F,MATCH(1,(TRIM(Innings!A:A)=TRIM(A8))*(TRIM(Innings!D:D)=TRIM(E8)),0))} -> 64 | AA8: {=INDEX(Innings!I:I,MATCH(1,(TRIM(Innings!A:A)=TRIM(A8))*(TRIM(Innings!D:D)=TRIM(E8)),0))} -> 4.22 | AB8: {=INDEX(Innings!J:J,MATCH(1,(TRIM(Innings!A:A)=TRIM(A8))*(TRIM(Innings!D:D)=TRIM(E8)),0))} -> 17 | AC8: {=INDEX(Innings!N:N,MATCH(1,(TRIM(Innings!A:A)=TRIM(A8))*(TRIM(Innings!D:D)=TRIM(E8)),0))} -> 0 | AD8: {=INDEX(Innings!S:S,MATCH(1,(TRIM(Innings!A:A)=TRIM(A8))*(TRIM(Innings!D:D)=TRIM(E8)),0))} -> 62 | AE8: {=INDEX(Innings!W:W,MATCH(1,(TRIM(Innings!A:A)=TRIM(A8))*(TRIM(Innings!D:D)=TRIM(E8)),0))} -> Failed | AF8: =IF(UPPER(TRIM(E8))=UPPER(TRIM(W8)),1,0) -> 0 | AG8: =(0.5*MAX(0,U8) + 0.3*MAX(0,V8) + 0.2*AF8*100) -> 5.71
A9: WPL2023_01 | B9: 1 | C9: P008 | D9: Sneh Rana | E9: GGTW | F9: Bowling Allrounder | G9: Middle Order | H9: 1 | I9: 2 | J9: 50 | K9: lbw | L9: 0.5 | M9: 4 | N9: 0 | O9: 43 | P9: 2 | Q9: 10.8 | R9: 28.4 | S9: 0 | T9: 0 | U9: 28.9 | V9: =MIN(10, MAX(0, ROUND(U9/10,0))) -> 3 | W9: =_xlfn.XLOOKUP(A9, Matches!A:A, Matches!L:L, "NA", 0) -> MIW | X9: =_xlfn.XLOOKUP(A9, Matches!A:A, Matches!J:J, "NA", 0) -> GGTW | Y9: =_xlfn.XLOOKUP(A9, Matches!A:A, Matches!F:F, "NA", 0) -> Dr.DY Patil Sports | Z9: {=INDEX(Innings!F:F,MATCH(1,(TRIM(Innings!A:A)=TRIM(A9))*(TRIM(Innings!D:D)=TRIM(E9)),0))} -> 64 | AA9: {=INDEX(Innings!I:I,MATCH(1,(TRIM(Innings!A:A)=TRIM(A9))*(TRIM(Innings!D:D)=TRIM(E9)),0))} -> 4.22 | AB9: {=INDEX(Innings!J:J,MATCH(1,(TRIM(Innings!A:A)=TRIM(A9))*(TRIM(Innings!D:D)=TRIM(E9)),0))} -> 17 | AC9: {=INDEX(Innings!N:N,MATCH(1,(TRIM(Innings!A:A)=TRIM(A9))*(TRIM(Innings!D:D)=TRIM(E9)),0))} -> 0 | AD9: {=INDEX(Innings!S:S,MATCH(1,(TRIM(Innings!A:A)=TRIM(A9))*(TRIM(Innings!D:D)=TRIM(E9)),0))} -> 62 | AE9: {=INDEX(Innings!W:W,MATCH(1,(TRIM(Innings!A:A)=TRIM(A9))*(TRIM(Innings!D:D)=TRIM(E9)),0))} -> Failed | AF9: =IF(UPPER(TRIM(E9))=UPPER(TRIM(W9)),1,0) -> 0 | AG9: =(0.5*MAX(0,U9) + 0.3*MAX(0,V9) + 0.2*AF9*100) -> 15.35
A10: WPL2023_01 | B10: 1 | C10: P009 | D10: Tanuja Kanwar | E10: GGTW | F10: Bowler | G10: Lower Order | H10: 0 | I10: 3 | J10: 0 | K10: caught | L10: 0 | M10: 2 | N10: 0 | O10: 12 | P10: 1 | Q10: 6 | R10: 13 | S10: 0 | T10: 0 | U10: 13 | V10: =MIN(10, MAX(0, ROUND(U10/10,0))) -> 1 | W10: =_xlfn.XLOOKUP(A10, Matches!A:A, Matches!L:L, "NA", 0) -> MIW | X10: =_xlfn.XLOOKUP(A10, Matches!A:A, Matches!J:J, "NA", 0) -> GGTW | Y10: =_xlfn.XLOOKUP(A10, Matches!A:A, Matches!F:F, "NA", 0) -> Dr.DY Patil Sports | Z10: {=INDEX(Innings!F:F,MATCH(1,(TRIM(Innings!A:A)=TRIM(A10))*(TRIM(Innings!D:D)=TRIM(E10)),0))} -> 64 | AA10: {=INDEX(Innings!I:I,MATCH(1,(TRIM(Innings!A:A)=TRIM(A10))*(TRIM(Innings!D:D)=TRIM(E10)),0))} -> 4.22 | AB10: {=INDEX(Innings!J:J,MATCH(1,(TRIM(Innings!A:A)=TRIM(A10))*(TRIM(Innings!D:D)=TRIM(E10)),0))} -> 17 | AC10: {=INDEX(Innings!N:N,MATCH(1,(TRIM(Innings!A:A)=TRIM(A10))*(TRIM(Innings!D:D)=TRIM(E10)),0))} -> 0 | AD10: {=INDEX(Innings!S:S,MATCH(1,(TRIM(Innings!A:A)=TRIM(A10))*(TRIM(Innings!D:D)=TRIM(E10)),0))} -> 62 | AE10: {=INDEX(Innings!W:W,MATCH(1,(TRIM(Innings!A:A)=TRIM(A10))*(TRIM(Innings!D:D)=TRIM(E10)),0))} -> Failed | AF10: =IF(UPPER(TRIM(E10))=UPPER(TRIM(W10)),1,0) -> 0 | AG10: =(0.5*MAX(0,U10) + 0.3*MAX(0,V10) + 0.2*AF10*100) -> 6.8
A11: WPL2023_01 | B11: 1 | C11: P010 | D11: Monica Patel | E11: GGTW | F11: Bowler | G11: Lower Order | H11: 10 | I11: 9 | J11: 111.11 | K11: bowled | L11: 11.11 | M11: 2 | N11: 0 | O11: 34 | P11: 0 | Q11: 17 | R11: -34 | S11: 0 | T11: 0 | U11: -22.89 | V11: =MIN(10, MAX(0, ROUND(U11/10,0))) -> 0 | W11: =_xlfn.XLOOKUP(A11, Matches!A:A, Matches!L:L, "NA", 0) -> MIW | X11: =_xlfn.XLOOKUP(A11, Matches!A:A, Matches!J:J, "NA", 0) -> GGTW | Y11: =_xlfn.XLOOKUP(A11, Matches!A:A, Matches!F:F, "NA", 0) -> Dr.DY Patil Sports | Z11: {=INDEX(Innings!F:F,MATCH(1,(TRIM(Innings!A:A)=TRIM(A11))*(TRIM(Innings!D:D)=TRIM(E11)),0))} -> 64 | AA11: {=INDEX(Innings!I:I,MATCH(1,(TRIM(Innings!A:A)=TRIM(A11))*(TRIM(Innings!D:D)=TRIM(E11)),0))} -> 4.22 | AB11: {=INDEX(Innings!J:J,MATCH(1,(TRIM(Innings!A:A)=TRIM(A11))*(TRIM(Innings!D:D)=TRIM(E11)),0))} -> 17 | AC11: {=INDEX(Innings!N:N,MATCH(1,(TRIM(Innings!A:A)=TRIM(A11))*(TRIM(Innings!D:D)=TRIM(E11)),0))} -> 0 | AD11: {=INDEX(Innings!S:S,MATCH(1,(TRIM(Innings!A:A)=TRIM(A11))*(TRIM(Innings!D:D)=TRIM(E11)),0))} -> 62 | AE11: {=INDEX(Innings!W:W,MATCH(1,(TRIM(Innings!A:A)=TRIM(A11))*(TRIM(Innings!D:D)=TRIM(E11)),0))} -> Failed | AF11: =IF(UPPER(TRIM(E11))=UPPER(TRIM(W11)),1,0) -> 0 | AG11: =(0.5*MAX(0,U11) + 0.3*MAX(0,V11) + 0.2*AF11*100) -> 0
A12: WPL2023_01 | B12: 1 | C12: P011 | D12: Mansi Joshi | E12: GGTW | F12: Bowler | G12: Lower Order | H12: 6 | I12: 19 | J12: 31.58 | K12: lbw | L12: 1.89 | M12: 2 | N12: 0 | O12: 17 | P12: 0 | Q12: 8.5 | R12: -17 | S12: 0 | T12: 0 | U12: -15.11 | V12: =MIN(10, MAX(0, ROUND(U12/10,0))) -> 0 | W12: =_xlfn.XLOOKUP(A12, Matches!A:A, Matches!L:L, "NA", 0) -> MIW | X12: =_xlfn.XLOOKUP(A12, Matches!A:A, Matches!J:J, "NA", 0) -> GGTW | Y12: =_xlfn.XLOOKUP(A12, Matches!A:A, Matches!F:F, "NA", 0) -> Dr.DY Patil Sports | Z12: {=INDEX(Innings!F:F,MATCH(1,(TRIM(Innings!A:A)=TRIM(A12))*(TRIM(Innings!D:D)=TRIM(E12)),0))} -> 64 | AA12: {=INDEX(Innings!I:I,MATCH(1,(TRIM(Innings!A:A)=TRIM(A12))*(TRIM(Innings!D:D)=TRIM(E12)),0))} -> 4.22 | AB12: {=INDEX(Innings!J:J,MATCH(1,(TRIM(Innings!A:A)=TRIM(A12))*(TRIM(Innings!D:D)=TRIM(E12)),0))} -> 17 | AC12: {=INDEX(Innings!N:N,MATCH(1,(TRIM(Innings!A:A)=TRIM(A12))*(TRIM(Innings!D:D)=TRIM(E12)),0))} -> 0 | AD12: {=INDEX(Innings!S:S,MATCH(1,(TRIM(Innings!A:A)=TRIM(A12))*(TRIM(Innings!D:D)=TRIM(E12)),0))} -> 62 | AE12: {=INDEX(Innings!W:W,MATCH(1,(TRIM(Innings!A:A)=TRIM(A12))*(TRIM(Innings!D:D)=TRIM(E12)),0))} -> Failed | AF12: =IF(UPPER(TRIM(E12))=UPPER(TRIM(W12)),1,0) -> 0 | AG12: =(0.5*MAX(0,U12) + 0.3*MAX(0,V12) + 0.2*AF12*100) -> 0
A13: WPL2023_01 | B13: 1 | C13: P012 | D13: Hayley Matthews | E13: MIW | F13: Batting Allrounder | G13: Opener | H13: 47 | I13: 31 | J13: 151.61 | K13: bowled | L13: 71.26 | M13: 1 | N13: 0 | O13: 8 | P13: 0 | Q13: 8 | R13: -16 | S13: 0 | T13: 0 | U13: 55.26 | V13: =MIN(10, MAX(0, ROUND(U13/10,0))) -> 6 | W13: =_xlfn.XLOOKUP(A13, Matches!A:A, Matches!L:L, "NA", 0) -> MIW | X13: =_xlfn.XLOOKUP(A13, Matches!A:A, Matches!J:J, "NA", 0) -> GGTW | Y13: =_xlfn.XLOOKUP(A13, Matches!A:A, Matches!F:F, "NA", 0) -> Dr.DY Patil Sports | Z13: {=INDEX(Innings!F:F,MATCH(1,(TRIM(Innings!A:A)=TRIM(A13))*(TRIM(Innings!D:D)=TRIM(E13)),0))} -> 207 | AA13: {=INDEX(Innings!I:I,MATCH(1,(TRIM(Innings!A:A)=TRIM(A13))*(TRIM(Innings!D:D)=TRIM(E13)),0))} -> 10.35 | AB13: {=INDEX(Innings!J:J,MATCH(1,(TRIM(Innings!A:A)=TRIM(A13))*(TRIM(Innings!D:D)=TRIM(E13)),0))} -> 44 | AC13: {=INDEX(Innings!N:N,MATCH(1,(TRIM(Innings!A:A)=TRIM(A13))*(TRIM(Innings!D:D)=TRIM(E13)),0))} -> 48 | AD13: {=INDEX(Innings!S:S,MATCH(1,(TRIM(Innings!A:A)=TRIM(A13))*(TRIM(Innings!D:D)=TRIM(E13)),0))} -> 44 | AE13: {=INDEX(Innings!W:W,MATCH(1,(TRIM(Innings!A:A)=TRIM(A13))*(TRIM(Innings!D:D)=TRIM(E13)),0))} -> NA | AF13: =IF(UPPER(TRIM(E13))=UPPER(TRIM(W13)),1,0) -> 1 | AG13: =(0.5*MAX(0,U13) + 0.3*MAX(0,V13) + 0.2*AF13*100) -> 49.43
... A1936: WPL2026_22 | B1936: 4 | C1936: P113 | D1936: Lauren Bell | E1936: RCBW | F1936: Bowler | G1936: DNB | H1936: 0 | I1936: 0 | J1936: 0 | K1936: DNB | L1936: 0 | M1936: 4 | N1936: 0 | O1936: 19 | P1936: 0 | Q1936: 4.8 | R1936: 0 | S1936: 0 | T1936: 0 | U1936: 0 | V1936: =MIN(10, MAX(0, ROUND(U1936/10,0))) -> 0 | W1936: =_xlfn.XLOOKUP(A1936, Matches!A:A, Matches!L:L, "NA", 0) -> RCBW | X1936: =_xlfn.XLOOKUP(A1936, Matches!A:A, Matches!J:J, "NA", 0) -> RCBW | Y1936: =_xlfn.XLOOKUP(A1936, Matches!A:A, Matches!F:F, "NA", 0) -> BCA Stadium, Kotambi | Z1936: {=INDEX(Innings!F:F,MATCH(1,(TRIM(Innings!A:A)=TRIM(A1936))*(TRIM(Innings!D:D)=TRIM(E1936)),0))} -> 204 | AA1936: {=INDEX(Innings!I:I,MATCH(1,(TRIM(Innings!A:A)=TRIM(A1936))*(TRIM(Innings!D:D)=TRIM(E1936)),0))} -> 10.37 | AB1936: {=INDEX(Innings!J:J,MATCH(1,(TRIM(Innings!A:A)=TRIM(A1936))*(TRIM(Innings!D:D)=TRIM(E1936)),0))} -> 59 | AC1936: {=INDEX(Innings!N:N,MATCH(1,(TRIM(Innings!A:A)=TRIM(A1936))*(TRIM(Innings!D:D)=TRIM(E1936)),0))} -> 35 | AD1936: {=INDEX(Innings!S:S,MATCH(1,(TRIM(Innings!A:A)=TRIM(A1936))*(TRIM(Innings!D:D)=TRIM(E1936)),0))} -> 24 | AE1936: {=INDEX(Innings!W:W,MATCH(1,(TRIM(Innings!A:A)=TRIM(A1936))*(TRIM(Innings!D:D)=TRIM(E1936)),0))} -> Successful | AF1936: =IF(UPPER(TRIM(E1936))=UPPER(TRIM(W1936)),1,0) -> 1 | AG1936: =(0.5*MAX(0,U1936) + 0.3*MAX(0,V1936) + 0.2*AF1936*100) -> 20

Sheet Players
A1: Match_id | B1: Season | C1: Player_id | D1: player_name | E1: team | F1: role | G1: battin_position | H1: runs_scored | I1: balls_faced | J1: strike_rate | K1: dismissal_type | L1: batting_impact_score | M1: overs_bowled | N1: maidens | O1: runs_conceded | P1: wickets_taken | Q1: economy | R1: bowling_impact_score | S1: catches | T1: runouts | U1: total_player_impact | V1: player_match_rating
A2: WPL2023_01 | B2: 1 | C2: P001 | D2: Beth Mooney | E2: GGTW | F2: WK-Batter | G2: Opener | H2: 0 | I2: 3 | J2: 0 | K2: retired out | L2: 0 | M2: 0 | N2: 0 | O2: 0 | P2: 0 | Q2: 0 | R2: 0 | S2: 0 | T2: 0 | U2: 0 | V2: =MIN(10, MAX(0, ROUND(U2/10,0))) -> 0
A3: WPL2023_01 | B3: 1 | C3: P002 | D3: Sabbhineni Meghana | E3: GGTW | F3: Batter | G3: Opener | H3: 2 | I3: 4 | J3: 50 | K3: bowled | L3: 1 | M3: 0 | N3: 0 | O3: 0 | P3: 0 | Q3: 0 | R3: 0 | S3: 0 | T3: 0 | U3: 1 | V3: =MIN(10, MAX(0, ROUND(U3/10,0))) -> 0
A4: WPL2023_01 | B4: 1 | C4: P003 | D4: Harleen Deol | E4: GGTW | F4: Batting Allrounder | G4: Top Order | H4: 0 | I4: 2 | J4: 0 | K4: caught | L4: 0 | M4: 0 | N4: 0 | O4: 0 | P4: 0 | Q4: 0 | R4: 0 | S4: 0 | T4: 0 | U4: 0 | V4: =MIN(10, MAX(0, ROUND(U4/10,0))) -> 0
A5: WPL2023_01 | B5: 1 | C5: P004 | D5: Ashleigh Gardner | E5: GGTW | F5: Batting Allrounder | G5: Middle Order | H5: 0 | I5: 1 | J5: 0 | K5: caught | L5: 0 | M5: 4 | N5: 0 | O5: 38 | P5: 1 | Q5: 9.5 | R5: 6 | S5: 0 | T5: 0 | U5: 6 | V5: =MIN(10, MAX(0, ROUND(U5/10,0))) -> 1
A6: WPL2023_01 | B6: 1 | C6: P005 | D6: Annabel Sutherland | E6: GGTW | F6: Bowling Allrounder | G6: Middle Order | H6: 6 | I6: 14 | J6: 42.86 | K6: bowled | L6: 2.57 | M6: 3 | N6: 0 | O6: 32 | P6: 0 | Q6: 10.7 | R6: -21.4 | S6: 0 | T6: 0 | U6: -18.83 | V6: =MIN(10, MAX(0, ROUND(U6/10,0))) -> 0
A7: WPL2023_01 | B7: 1 | C7: P006 | D7: Dayalan Hemalatha | E7: GGTW | F7: Batter | G7: Middle Order | H7: 29 | I7: 23 | J7: 126.09 | K7: not out | L7: 36.57 | M7: 0 | N7: 0 | O7: 0 | P7: 0 | Q7: 0 | R7: 0 | S7: 0 | T7: 0 | U7: 36.57 | V7: =MIN(10, MAX(0, ROUND(U7/10,0))) -> 4
A8: WPL2023_01 | B8: 1 | C8: P007 | D8: Georgia Wareham | E8: GGTW | F8: Bowler | G8: Lower Order | H8: 8 | I8: 11 | J8: 72.73 | K8: bowled | L8: 5.82 | M8: 3 | N8: 0 | O8: 30 | P8: 1 | Q8: 10 | R8: 5 | S8: 0 | T8: 0 | U8: 10.82 | V8: =MIN(10, MAX(0, ROUND(U8/10,0))) -> 1
A9: WPL2023_01 | B9: 1 | C9: P008 | D9: Sneh Rana | E9: GGTW | F9: Bowling Allrounder | G9: Middle Order | H9: 1 | I9: 2 | J9: 50 | K9: lbw | L9: 0.5 | M9: 4 | N9: 0 | O9: 43 | P9: 2 | Q9: 10.8 | R9: 28.4 | S9: 0 | T9: 0 | U9: 28.9 | V9: =MIN(10, MAX(0, ROUND(U9/10,0))) -> 3
A10: WPL2023_01 | B10: 1 | C10: P009 | D10: Tanuja Kanwar | E10: GGTW | F10: Bowler | G10: Lower Order | H10: 0 | I10: 3 | J10: 0 | K10: caught | L10: 0 | M10: 2 | N10: 0 | O10: 12 | P10: 1 | Q10: 6 | R10: 13 | S10: 0 | T10: 0 | U10: 13 | V10: =MIN(10, MAX(0, ROUND(U10/10,0))) -> 1
A11: WPL2023_01 | B11: 1 | C11: P010 | D11: Monica Patel | E11: GGTW | F11: Bowler | G11: Lower Order | H11: 10 | I11: 9 | J11: 111.11 | K11: bowled | L11: 11.11 | M11: 2 | N11: 0 | O11: 34 | P11: 0 | Q11: 17 | R11: -34 | S11: 0 | T11: 0 | U11: -22.89 | V11: =MIN(10, MAX(0, ROUND(U11/10,0))) -> 0
A12: WPL2023_01 | B12: 1 | C12: P011 | D12: Mansi Joshi | E12: GGTW | F12: Bowler | G12: Lower Order | H12: 6 | I12: 19 | J12: 31.58 | K12: lbw | L12: 1.89 | M12: 2 | N12: 0 | O12: 17 | P12: 0 | Q12: 8.5 | R12: -17 | S12: 0 | T12: 0 | U12: -15.11 | V12: =MIN(10, MAX(0, ROUND(U12/10,0))) -> 0
A13: WPL2023_01 | B13: 1 | C13: P012 | D13: Hayley Matthews | E13: MIW | F13: Batting Allrounder | G13: Opener | H13: 47 | I13: 31 | J13: 151.61 | K13: bowled | L13: 71.26 | M13: 1 | N13: 0 | O13: 8 | P13: 0 | Q13: 8 | R13: -16 | S13: 0 | T13: 0 | U13: 55.26 | V13: =MIN(10, MAX(0, ROUND(U13/10,0))) -> 6
... A1936: WPL2026_22 | B1936: 4 | C1936: P113 | D1936: Lauren Bell | E1936: RCBW | F1936: Bowler | G1936: DNB | H1936: 0 | I1936: 0 | J1936: 0 | K1936: DNB | L1936: 0 | M1936: 4 | N1936: 0 | O1936: 19 | P1936: 0 | Q1936: 4.8 | R1936: 0 | S1936: 0 | T1936: 0 | U1936: 0 | V1936: =MIN(10, MAX(0, ROUND(U1936/10,0))) -> 0

Sheet Sheet1
B2: WPL2026_22 | C2: 4 | D2: P117 | E2: Lizelle Lee | F2: DCW | G2: WK-Batter | H2: Opener | I2: 37 | J2: 30 | K2: 123.33 | L2: caught | M2: 40 | N2: 0 | O2: 0 | P2: 0 | Q2: 0 | R2: 0 | S2: 0 | T2: 0 | U2: 0 | V2: 40 | W2: 4
B3: WPL2026_22 | C3: 4 | D3: P034 | E3: Shafali Verma | F3: DCW | G3: Batter | H3: Opener | I3: 20 | J3: 13 | K3: 153.85 | L3: caught | M3: 25 | N3: 1 | O3: 0 | P3: 9 | Q3: 0 | R3: 9 | S3: 0 | T3: 0 | U3: 0 | V3: 25 | W3: 3
B4: WPL2026_22 | C4: 4 | D4: P066 | E4: Laura Wolvaardt | F4: DCW | G4: Batter | H4: Top Order | I4: 44 | J4: 25 | K4: 176 | L4: run out | M4: 50 | N4: 0 | O4: 0 | P4: 0 | Q4: 0 | R4: 0 | S4: 0 | T4: 0 | U4: 0 | V4: 50 | W4: 5
B5: WPL2026_22 | C5: 4 | D5: P037 | E5: Jemimah Rodrigues | F5: DCW | G5: Batter | H5: Top Order | I5: 57 | J5: 37 | K5: 154.05 | L5: caught | M5: 65 | N5: 0 | O5: 0 | P5: 0 | Q5: 0 | R5: 0 | S5: 0 | T5: 0 | U5: 0 | V5: 65 | W5: 7
B6: WPL2026_22 | C6: 4 | D6: P036 | E6: Marizanne Kapp | F6: DCW | G6: Allrounder | H6: Middle Order | I6: 0 | J6: 0 | K6: 0 | L6: DNB | M6: 0 | N6: 4 | O6: 0 | P6: 38 | Q6: 0 | R6: 9.5 | S6: 0 | T6: 0 | U6: 0 | V6: 0 | W6: 0
B7: WPL2026_22 | C7: 4 | D7: P107 | E7: Chinelle Henry | F7: DCW | G7: Allrounder | H7: Middle Order | I7: 35 | J7: 15 | K7: 233.33 | L7: not out | M7: 50 | N7: 4 | O7: 0 | P7: 34 | Q7: 2 | R7: 8.5 | S7: 50 | T7: 0 | U7: 0 | V7: 100 | W7: 10
B8: WPL2026_22 | C8: 4 | D8: P100 | E8: Niki Prasad | F8: DCW | G8: Allrounder | H8: DNB | I8: 0 | J8: 0 | K8: 0 | L8: DNB | M8: 0 | N8: 0 | O8: 0 | P8: 0 | Q8: 0 | R8: 0 | S8: 0 | T8: 0 | U8: 0 | V8: 0 | W8: 0
B9: WPL2026_22 | C9: 4 | D9: P008 | E9: Sneh Rana | F9: DCW | G9: Allrounder | H9: DNB | I9: 0 | J9: 0 | K9: 0 | L9: DNB | M9: 0 | N9: 1 | O9: 0 | P9: 15 | Q9: 0 | R9: 15 | S9: 0 | T9: 0 | U9: 0 | V9: 0 | W9: 0
B10: WPL2026_22 | C10: 4 | D10: P062 | E10: Minnu Mani | F10: DCW | G10: Allrounder | H10: DNB | I10: 0 | J10: 0 | K10: 0 | L10: DNB | M10: 0 | N10: 2 | O10: 0 | P10: 19 | Q10: 1 | R10: 9.5 | S10: 25 | T10: 0 | U10: 0 | V10: 25 | W10: 3
B11: WPL2026_22 | C11: 4 | D11: P118 | E11: Shree Charani | F11: DCW | G11: Bowler | H11: DNB | I11: 0 | J11: 0 | K11: 0 | L11: DNB | M11: 0 | N11: 3.4 | O11: 0 | P11: 46 | Q11: 0 | R11: 12.5 | S11: 0 | T11: 0 | U11: 0 | V11: 0 | W11: 0
B12: WPL2026_22 | C12: 4 | D12: P119 | E12: Nandani Sharma | F12: DCW | G12: Bowler | H12: DNB | I12: 0 | J12: 0 | K12: 0 | L12: DNB | M12: 0 | N12: 4 | O12: 0 | P12: 41 | Q12: 1 | R12: 10.2 | S12: 25 | T12: 0 | U12: 0 | V12: 25 | W12: 3
B14: WPL2026_22 | C14: 4 | D14: P049 | E14: Grace Harris | F14: RCB | G14: WK-Batter | H14: Opener | I14: 9 | J14: 7 | K14: 128.57 | L14: bowled | M14: 10 | N14: 0 | O14: 0 | P14: 0 | Q14: 0 | R14: 0 | S14: 0 | T14: 0 | U14: 0 | V14: 10 | W14: 1
... B24: WPL2026_22 | C24: 4 | D24: P113 | E24: Lauren Bell | F24: RCB | G24: Bowler | H24: DNB | I24: 0 | J24: 0 | K24: 0 | L24: DNB | M24: 0 | N24: 4 | O24: 0 | P24: 19 | Q24: 0 | R24: 4.8 | S24: 0 | T24: 0 | U24: 0 | V24: 0 | W24: 0

Sheet all players
B3: P001 | C3: Beth Mooney
B4: P002 | C4: Sabbhineni Meghana
B5: P003 | C5: Harleen Deol
B6: P004 | C6: Ashleigh Gardner
B7: P005 | C7: Annabel Sutherland
B8: P006 | C8: Dayalan Hemalatha
B9: P007 | C9: Georgia Wareham
B10: P008 | C10: Sneh Rana
B11: P009 | C11: Tanuja Kanwar
B12: P010 | C12: Monica Patel
B13: P011 | C13: Mansi Joshi
B14: P012 | C14: Hayley Matthews
... B139: P137 | C139: Danielle Gibson
